Workbook

Sheet HW config
A1: Project : | B1: Tests_Jay_Nemo_MOKA
A2: Customer : | B2: T.EN
A4: Document nr : | B4: /
A6: Base Unit: | B6: Nemo - CompactCom 40 DP
B8: Emplac. | C8: Identification DP | E8: N° de référence / Description | J8: Longueur entrée | L8: Longueur sortie
J9: Adr. Déb | K9: Adr. Fin | L9: Adr. Déb | M9: Adr. Fin
B10: 1 | C10: 67 | E10: Identity Code TM (1*UINT32) | J10: 1100 | K10: 1103
B11: 2 | C11: 67 | E11: Identity Code OM (1*UINT32) | J11: 1104 | K11: 1107
B12: 3 | C12: 67 | E12: Alarms and status (2*UINT16) | J12: 1108 | K12: 1111
B13: 4 | C13: 67 | E13: Last Event (2*UINT32) | J13: 1112 | K13: 1119
B14: 5 | C14: 67 | E14: Info (4*UINT16) | J14: 1120 | K14: 1127
B15: 6 | C15: 67 | E15: OBoolNetwork 1..64 (4*UINT) | J15: 1128 | K15: 1135
B16: 7 | C16: 67 | E16: ONumNetwork 1..16 (16*SINT) | J16: 1136 | K16: 1167
B17: 8 | C17: 67 | E17: OSPY 1..8 (8*SINT16) | J17: 1168 | K17: 1183
B18: 9 | C18: 131 | E18: IBoolNetwork 1..64 (4*UINT16) | L18: 1100 | M18: 1107
B19: 10 | C19: 131 | E19: INumNetwork 1..16 (16*SINT16) | L19: 1108 | M19: 1139
B20: 11 | C20: 131 | E20: IWHC 1..2 (2*UINT32) | L20: 1140 | M20: 1147
B21: 12 | C21: 16 | E21: ISPY 1..2 (2*SINT) | L21: 1148 | M21: 1151

Sheet Radio Layout
A1: Project : | B1: Tests_Jay_Nemo_MOKA
A2: Customer : | B2: T.EN
A4: Document nr : | B4: /
A6: Base Unit: | B6: NEMO - CompactCom 40 DP | F6: réf: | G6: MN10003
G7: 190818001R1
A8: Emetteur: | B8: MOKA | F8: réf: | G8: MM20037
G9: 190818001E1
B39: T.EN layout for project
B42: A1 | C42: Lock / Unlock command
B44: A3 | C44: Open / Close ERS
B46: A6 | C46: Slow speed / High speed
B48: A8 | C48: Start / Stop pump
B50: A12 | C50: Arm's selector | E50: (10 positions)
B53: AXIS1 | C53: AXANA1 - Joystick for Slewing
B54: AXIS2 | C54: AXANA2 - Joystick for Outboard
B55: AXIS3 | C55: AXANA3 - Joystick for Coupler
B56: AXIS4 | C56: AXANA4 - Joystick for Inboard

Sheet Data System
A1: Project : | B1: Tests_Jay_Nemo_MOKA
A2: Customer : | B2: T.EN
A4: Document nr : | B4: /
A7: iDialog software | Y7: STEP7 Siemens software
B8: backup filename: | D8: FPI199FU_ProfibusDP(WHC_V2) | Z8: project name: | AC8: FMC_REMAN_V5_3_JAY
B10: Programmation | Z10: Programmation
D11: Mapping | AC11: Hardware
V28: Unique Identity Code for Transmitter
V30: Unique Identity Code for the Receiver
Y97: Entrée PLC configurée ds HW | AC97: ='HW config'!J10 -> 1100 | BC97: Entrée PLC configurée ds HW | BG97: ='HW config'!J11 -> 1104
R99: Radio action | V99: bit | Y99: PLC description | AC99: Input number | AE99: Type | AX99: Radio action | BB99: bit | BC99: PLC description | BG99: Input number | BI99: Type
R100: Identity Code TM Bits 0-19 little indian | V100: 0 | Y100: ODataSystemNetwork.01 | AB100: E | AC100: =AC97 -> 1100 | AD100: .0 | AE100: Int or Real (32)?? | AH100: 1 Byte | AL100: 1er Word | AP100: 1er Dword | AX100: Identity Code OM Bits 0-19 little indian | BB100: 0 | BC100: ODataSystemNetwork.02 | BF100: E | BG100: =BG97 -> 1104 | BH100: .0 | BI100: Int or Real (32)?? | BK100: 1 Byte [EB260] | BM100: 1er Word [EW260] | BO100: 1er Dword [ED260]
V101: 1 | AB101: E | AC101: =AC97 -> 1100 | AD101: .1 | BB101: 1 | BF101: E | BG101: =BG97 -> 1104 | BH101: .1
V102: 2 | AB102: E | AC102: =AC97 -> 1100 | AD102: .2 | BB102: 2 | BF102: E | BG102: =BG97 -> 1104 | BH102: .2
V103: 3 | AB103: E | AC103: =AC97 -> 1100 | AD103: .3 | BB103: 3 | BF103: E | BG103: =BG97 -> 1104 | BH103: .3
V104: 4 | AB104: E | AC104: =AC97 -> 1100 | AD104: .4 | AG104: [EB | AH104: =AC100 -> 1100 | AI104: ] | BB104: 4 | BF104: E | BG104: =BG97 -> 1104 | BH104: .4
V105: 5 | AB105: E | AC105: =AC97 -> 1100 | AD105: .5 | BB105: 5 | BF105: E | BG105: =BG97 -> 1104 | BH105: .5
V106: 6 | AB106: E | AC106: =AC97 -> 1100 | AD106: .6 | BB106: 6 | BF106: E | BG106: =BG97 -> 1104 | BH106: .6
V107: 7 | AB107: E | AC107: =AC97 -> 1100 | AD107: .7 | BB107: 7 | BF107: E | BG107: =BG97 -> 1104 | BH107: .7
AK108: [EW | AL108: =AC100 -> 1100 | AM108: ]
V109: 8 | AB109: E | AC109: =AC97+1 -> 1101 | AD109: .0 | AH109: 1 Byte | BB109: 8 | BF109: E | BG109: =BG97+1 -> 1105 | BH109: .0 | BK109: 1 Byte [EB261]
V110: 9 | AB110: E | AC110: =AC97+1 -> 1101 | AD110: .1 | BB110: 9 | BF110: E | BG110: =BG97+1 -> 1105 | BH110: .1
V111: 10 | AB111: E | AC111: =AC97+1 -> 1101 | AD111: .2 | BB111: 10 | BF111: E | BG111: =BG97+1 -> 1105 | BH111: .2
V112: 11 | AB112: E | AC112: =AC97+1 -> 1101 | AD112: .3 | BB112: 11 | BF112: E | BG112: =BG97+1 -> 1105 | BH112: .3
V113: 12 | AB113: E | AC113: =AC97+1 -> 1101 | AD113: .4 | AG113: [EB | AH113: =AC109 -> 1101 | AI113: ] | BB113: 12 | BF113: E | BG113: =BG97+1 -> 1105 | BH113: .4
V114: 13 | AB114: E | AC114: =AC97+1 -> 1101 | AD114: .5 | BB114: 13 | BF114: E | BG114: =BG97+1 -> 1105 | BH114: .5
V115: 14 | AB115: E | AC115: =AC97+1 -> 1101 | AD115: .6 | BB115: 14 | BF115: E | BG115: =BG97+1 -> 1105 | BH115: .6
V116: 15 | AB116: E | AC116: =AC97+1 -> 1101 | AD116: .7 | BB116: 15 | BF116: E | BG116: =BG97+1 -> 1105 | BH116: .7
AO117: [ED | AP117: =AC100 -> 1100 | AQ117: ]
V118: 16 | AB118: E | AC118: =AC97+2 -> 1102 | AD118: .0 | AH118: 1 Byte | AL118: 2ème Word | BB118: 16 | BF118: E | BG118: =BG97+2 -> 1106 | BH118: .0 | BK118: 1 Byte [EB262] | BM118: 2ème Word [EW262]
V119: 17 | AB119: E | AC119: =AC97+2 -> 1102 | AD119: .1 | BB119: 17 | BF119: E | BG119: =BG97+2 -> 1106 | BH119: .1
V120: 18 | AB120: E | AC120: =AC97+2 -> 1102 | AD120: .2 | BB120: 18 | BF120: E | BG120: =BG97+2 -> 1106 | BH120: .2
V121: 19 | AB121: E | AC121: =AC97+2 -> 1102 | AD121: .3 | BB121: 19 | BF121: E | BG121: =BG97+2 -> 1106 | BH121: .3
V122: 20 | AB122: E | AC122: =AC97+2 -> 1102 | AD122: .4 | AG122: [EB | AH122: =AC118 -> 1102 | AI122: ] | BB122: 20 | BF122: E | BG122: =BG97+2 -> 1106 | BH122: .4
V123: 21 | AB123: E | AC123: =AC97+2 -> 1102 | AD123: .5 | BB123: 21 | BF123: E | BG123: =BG97+2 -> 1106 | BH123: .5
V124: 22 | AB124: E | AC124: =AC97+2 -> 1102 | AD124: .6 | BB124: 22 | BF124: E | BG124: =BG97+2 -> 1106 | BH124: .6
V125: 23 | AB125: E | AC125: =AC97+2 -> 1102 | AD125: .7 | BB125: 23 | BF125: E | BG125: =BG97+2 -> 1106 | BH125: .7
AK126: [EW | AL126: =AC118 -> 1102 | AM126: ]
V127: 24 | AB127: E | AC127: =AC97+3 -> 1103 | AD127: .0 | AH127: 1 Byte | BB127: 24 | BF127: E | BG127: =BG97+3 -> 1107 | BH127: .0 | BK127: 1 Byte [EB263]
V128: 25 | AB128: E | AC128: =AC97+3 -> 1103 | AD128: .1 | BB128: 25 | BF128: E | BG128: =BG97+3 -> 1107 | BH128: .1
...

Sheet Logical Output.Transceiver->PLC
A1: Project : | B1: Tests_Jay_Nemo_MOKA
A2: Customer : | B2: T.EN
A4: Document nr : | B4: /
A7: iDialog software | Y7: STEP7 Siemens software
B8: backup filename: | D8: FPI199FU_ProfibusDP(WHC_V2) | Z8: project name: | AC8: FMC_REMAN_V5_3_JAY
B10: Programmation | Z10: Programmation
D11: Mapping | AC11: Hardware
Y97: Entrée PLC configurée ds HW | AC97: ='HW config'!J15 -> 1128
R99: Radio action | V99: bit | W99: SIEMENS CONDUCTIX | X99: N° | Y99: PLC description | AC99: Input number | AE99: Type
R100: A8 - Pos01 : A8 - START PUMP | V100: 0 | W100: 8 | X100: 0 | Y100: OBoolNetwork.9 | AB100: E | AC100: =AC97 -> 1128 | AD100: .0 | AE100: Boolean | AH100: 1 Byte | AL100: 1er Word
R101: A8 - Pos02 : A8 - STOP PUMP | V101: 1 | W101: 9 | X101: 1 | Y101: OBoolNetwork.10 | AB101: E | AC101: =AC97 -> 1128 | AD101: .1 | AE101: Boolean
R102: A12 - Pos01 : A12 - ARM SELECT | V102: 2 | W102: 10 | X102: 2 | Y102: OBoolNetwork.11 | AB102: E | AC102: =AC97 -> 1128 | AD102: .2 | AE102: Boolean
R103: A12 - Pos02 : A12 - ARM SELECT | V103: 3 | W103: 11 | X103: 3 | Y103: OBoolNetwork.12 | AB103: E | AC103: =AC97 -> 1128 | AD103: .3 | AE103: Boolean
R104: A12 - Pos03 : A12 - ARM SELECT | V104: 4 | W104: 12 | X104: 4 | Y104: OBoolNetwork.13 | AB104: E | AC104: =AC97 -> 1128 | AD104: .4 | AE104: Boolean | AG104: [EB | AH104: =AC100 -> 1128 | AI104: ]
R105: A12 - Pos04 : A12 - ARM SELECT | V105: 5 | W105: 13 | X105: 5 | Y105: OBoolNetwork.14 | AB105: E | AC105: =AC97 -> 1128 | AD105: .5 | AE105: Boolean
R106: A12 - Pos05 : A12 - ARM SELECT | V106: 6 | W106: 14 | X106: 6 | Y106: OBoolNetwork.15 | AB106: E | AC106: =AC97 -> 1128 | AD106: .6 | AE106: Boolean
R107: A12 - Pos06 : A12 - ARM SELECT | V107: 7 | W107: 15 | X107: 7 | Y107: OBoolNetwork.16 | AB107: E | AC107: =AC97 -> 1128 | AD107: .7 | AE107: Boolean
AK108: [EW | AL108: =AC100 -> 1128 | AM108: ]
R109: F3 - Pos00 : F3-VALID | V109: 0 | W109: 0 | X109: 8 | Y109: OBoolNetwork.1 | AB109: E | AC109: =AC97+1 -> 1129 | AD109: .0 | AE109: Boolean | AH109: 1 Byte
R110: F3 - Pos01 : F3-VALID | V110: 1 | W110: 1 | X110: 9 | Y110: OBoolNetwork.2 | AB110: E | AC110: =AC97+1 -> 1129 | AD110: .1 | AE110: Boolean
R111: A1 - Pos01 : A1 - Déverrouillage | V111: 2 | W111: 2 | X111: 10 | Y111: OBoolNetwork.3 | AB111: E | AC111: =AC97+1 -> 1129 | AD111: .2 | AE111: Boolean
R112: A1 - Pos02 : A1 - Vérrouillage | V112: 3 | W112: 3 | X112: 11 | Y112: OBoolNetwork.4 | AB112: E | AC112: =AC97+1 -> 1129 | AD112: .3 | AE112: Boolean
R113: A3 - Pos01 : A3 - Open ERS VALVE | V113: 4 | W113: 4 | X113: 12 | Y113: OBoolNetwork.5 | AB113: E | AC113: =AC97+1 -> 1129 | AD113: .4 | AE113: Boolean | AG113: [EB | AH113: =AC109 -> 1129 | AI113: ]
R114: A3 - Pos02 : A3 - Close ERS VALVE | V114: 5 | W114: 5 | X114: 13 | Y114: OBoolNetwork.6 | AB114: E | AC114: =AC97+1 -> 1129 | AD114: .5 | AE114: Boolean
R115: A6 - Pos01 : A6 - PV | V115: 6 | W115: 6 | X115: 14 | Y115: OBoolNetwork.7 | AB115: E | AC115: =AC97+1 -> 1129 | AD115: .6 | AE115: Boolean
R116: A6 - Pos02 : A6 - GV | V116: 7 | W116: 7 | X116: 15 | Y116: OBoolNetwork.8 | AB116: E | AC116: =AC97+1 -> 1129 | AD116: .7 | AE116: Boolean
R119: free | V119: 0 | W119: 24 | X119: 16 | Y119: OBoolNetwork.25 | AB119: E | AC119: =AC97+2 -> 1130 | AD119: .0 | AE119: Boolean | AH119: 1 Byte | AL119: 2ème Word
R120: free | V120: 1 | W120: 25 | X120: 17 | Y120: OBoolNetwork.26 | AB120: E | AC120: =AC97+2 -> 1130 | AD120: .1 | AE120: Boolean
R121: free | V121: 2 | W121: 26 | X121: 18 | Y121: OBoolNetwork.27 | AB121: E | AC121: =AC97+2 -> 1130 | AD121: .2 | AE121: Boolean
R122: free | V122: 3 | W122: 27 | X122: 19 | Y122: OBoolNetwork.28 | AB122: E | AC122: =AC97+2 -> 1130 | AD122: .3 | AE122: Boolean
R123: free | V123: 4 | W123: 28 | X123: 20 | Y123: OBoolNetwork.29 | AB123: E | AC123: =AC97+2 -> 1130 | AD123: .4 | AE123: Boolean | AG123: [EB | AH123: =AC119 -> 1130 | AI123: ]
R124: free | V124: 5 | W124: 29 | X124: 21 | Y124: OBoolNetwork.30 | AB124: E | AC124: =AC97+2 -> 1130 | AD124: .5 | AE124: Boolean
R125: free | V125: 6 | W125: 30 | X125: 22 | Y125: OBoolNetwork.31 | AB125: E | AC125: =AC97+2 -> 1130 | AD125: .6 | AE125: Boolean
R126: free | V126: 7 | W126: 31 | X126: 23 | Y126: OBoolNetwork.32 | AB126: E | AC126: =AC97+2 -> 1130 | AD126: .7 | AE126: Boolean
AK127: [EW | AL127: =AC119 -> 1130 | AM127: ]
R128: A12 - Pos07 : A12 - ARM SELECT | V128: 0 | W128: 16 | X128: 24 | Y128: OBoolNetwork.17 | AB128: E | AC128: =AC97+3 -> 1131 | AD128: .0 | AE128: Boolean | AH128: 1 Byte
R129: A12 - Pos08 : A12 - ARM SELECT | V129: 1 | W129: 17 | X129: 25 | Y129: OBoolNetwork.18 | AB129: E | AC129: =AC97+3 -> 1131 | AD129: .1 | AE129: Boolean
R130: A12 - Pos09 : A12 - ARM SELECT | V130: 2 | W130: 18 | X130: 26 | Y130: OBoolNetwork.19 | AB130: E | AC130: =AC97+3 -> 1131 | AD130: .2 | AE130: Boolean
R131: A12 - Pos10 : A12 - ARM SELECT | V131: 3 | W131: 19 | X131: 27 | Y131: OBoolNetwork.20 | AB131: E | AC131: =AC97+3 -> 1131 | AD131: .3 | AE131: Boolean
R132: AXIS3 - Pos00 : AXANA3 - COUPLER | V132: 4 | W132: 20 | X132: 28 | Y132: OBoolNetwork.21 | AB132: E | AC132: =AC97+3 -> 1131 | AD132: .4 | AE132: Boolean | AG132: [EB | AH132: =AC128 -> 1131 | AI132: ]
...

Sheet Num. output.Transceiver-> PLC
A1: Project : | B1: Tests_Jay_Nemo_MOKA
A2: Customer : | B2: T.EN
A4: Document nr : | B4: /
A7: iDialog software | W7: STEP7 Siemens software
B8: backup filename: | D8: FPI199FU_ProfibusDP(WHC_V2) | X8: project name: | AA8: FMC_REMAN_V5_3_JAY
B10: Programmation | X10: Programmation
D11: Mapping | AA11: Hardware
W97: Entrée PLC configurée ds HW | AA97: ='HW config'!J16 -> 1136
R99: Radio action | V99: bit | W99: PLC description | AA99: Input number | AC99: Type
I100: Valeurs: | R100: AXANA1 - SLEWING | V100: 0 | W100: ONumNetwork.01 | Z100: E | AA100: =AA97 -> 1136 | AB100: .0 | AC100: Int (16) | AF100: 1 Byte | AJ100: 1er Word
J101: -100 | K101: Mouvement de Slewing à gauche | V101: 1 | Z101: E | AA101: =AA97 -> 1136 | AB101: .1
J102: 0 | K102: Aucun mouvement | V102: 2 | Z102: E | AA102: =AA97 -> 1136 | AB102: .2
J103: 100 | K103: Mouvement de Slewing à droite | V103: 3 | Z103: E | AA103: =AA97 -> 1136 | AB103: .3
V104: 4 | Z104: E | AA104: =AA97 -> 1136 | AB104: .4 | AE104: [EB | AF104: =AA100 -> 1136 | AG104: ]
V105: 5 | Z105: E | AA105: =AA97 -> 1136 | AB105: .5
V106: 6 | Z106: E | AA106: =AA97 -> 1136 | AB106: .6
V107: 7 | Z107: E | AA107: =AA97 -> 1136 | AB107: .7
AI108: [EW | AJ108: =AA100 -> 1136 | AK108: ]
V109: 8 | Z109: E | AA109: =AA97+1 -> 1137 | AB109: .0 | AF109: 1 Byte
V110: 9 | Z110: E | AA110: =AA97+1 -> 1137 | AB110: .1
V111: 10 | Z111: E | AA111: =AA97+1 -> 1137 | AB111: .2
V112: 11 | Z112: E | AA112: =AA97+1 -> 1137 | AB112: .3
V113: 12 | Z113: E | AA113: =AA97+1 -> 1137 | AB113: .4 | AE113: [EB | AF113: =AA109 -> 1137 | AG113: ]
V114: 13 | Z114: E | AA114: =AA97+1 -> 1137 | AB114: .5
V115: 14 | Z115: E | AA115: =AA97+1 -> 1137 | AB115: .6
V116: 15 | Z116: E | AA116: =AA97+1 -> 1137 | AB116: .7
R119: AXANA1 - SLEWING | V119: 0 | W119: ONumNetwork.02 | Z119: E | AA119: =AA97+2 -> 1138 | AB119: .0 | AC119: Int (16) | AF119: 1 Byte | AJ119: 2ème Word
I120: Valeurs: | V120: 1 | Z120: E | AA120: =AA97+2 -> 1138 | AB120: .1
J121: 2 | K121: Mouvement de Slewing à gauche | V121: 2 | Z121: E | AA121: =AA97+2 -> 1138 | AB121: .2
J122: 6 | K122: Aucun mouvement | V122: 3 | Z122: E | AA122: =AA97+2 -> 1138 | AB122: .3
J123: 10 | K123: Mouvement de Slewing à droite | V123: 4 | Z123: E | AA123: =AA97+2 -> 1138 | AB123: .4 | AE123: [EB | AF123: =AA119 -> 1138 | AG123: ]
V124: 5 | Z124: E | AA124: =AA97+2 -> 1138 | AB124: .5
V125: 6 | Z125: E | AA125: =AA97+2 -> 1138 | AB125: .6
V126: 7 | Z126: E | AA126: =AA97+2 -> 1138 | AB126: .7
AI127: [EW | AJ127: =AA119 -> 1138 | AK127: ]
V128: 8 | Z128: E | AA128: =AA97+3 -> 1139 | AB128: .0 | AF128: 1 Byte
V129: 9 | Z129: E | AA129: =AA97+3 -> 1139 | AB129: .1
V130: 10 | Z130: E | AA130: =AA97+3 -> 1139 | AB130: .2
V131: 11 | Z131: E | AA131: =AA97+3 -> 1139 | AB131: .3
V132: 12 | Z132: E | AA132: =AA97+3 -> 1139 | AB132: .4 | AE132: [EB | AF132: =AA128 -> 1139 | AG132: ]
...

Sheet Num. input.PLC->Transceiver 
A1: Project : | B1: Tests_Jay_Nemo_MOKA
A2: Customer : | B2: T.EN
A4: Document nr : | B4: /
A7: iDialog software | X7: STEP7 Siemens software
B8: backup filename: | D8: FPI199FU_ProfibusDP(WHC_V2) | Y8: project name: | AB8: FMC_REMAN_V5_3_JAY
B10: Programmation | Y10: Programmation
D11: Mapping | AB11: Hardware
X96: Sortie PLC configurée ds HW | AB96: ='HW config'!L19 -> 1108
R98: Radio action | V98: bit | W98: N° | X98: PLC description | AB98: Input number | AD98: Type
R99: Num01 | V99: 0 | W99: 0 | X99: INumNetwork.01 | AA99: A | AB99: =AB96 -> 1108 | AC99: .0 | AD99: Int (16) | AG99: 1 Byte | AK99: 1er Word
V100: 1 | W100: 1 | AA100: A | AB100: =AB96 -> 1108 | AC100: .1
V101: 2 | W101: 2 | AA101: A | AB101: =AB96 -> 1108 | AC101: .2
V102: 3 | W102: 3 | AA102: A | AB102: =AB96 -> 1108 | AC102: .3
V103: 4 | W103: 4 | AA103: A | AB103: =AB96 -> 1108 | AC103: .4 | AF103: [AB | AG103: =AB99 -> 1108 | AH103: ]
V104: 5 | W104: 5 | AA104: A | AB104: =AB96 -> 1108 | AC104: .5
V105: 6 | W105: 6 | AA105: A | AB105: =AB96 -> 1108 | AC105: .6
V106: 7 | W106: 7 | AA106: A | AB106: =AB96 -> 1108 | AC106: .7
AJ107: [AW | AK107: =AB99 -> 1108 | AL107: ]
V108: 0 | W108: 8 | AA108: A | AB108: =AB96+1 -> 1109 | AC108: .0 | AG108: 1 Byte
V109: 1 | W109: 9 | AA109: A | AB109: =AB96+1 -> 1109 | AC109: .1
V110: 2 | W110: 10 | AA110: A | AB110: =AB96+1 -> 1109 | AC110: .2
V111: 3 | W111: 11 | AA111: A | AB111: =AB96+1 -> 1109 | AC111: .3
V112: 4 | W112: 12 | AA112: A | AB112: =AB96+1 -> 1109 | AC112: .4 | AF112: [AB | AG112: =AB108 -> 1109 | AH112: ]
V113: 5 | W113: 13 | AA113: A | AB113: =AB96+1 -> 1109 | AC113: .5
V114: 6 | W114: 14 | AA114: A | AB114: =AB96+1 -> 1109 | AC114: .6
V115: 7 | W115: 15 | AA115: A | AB115: =AB96+1 -> 1109 | AC115: .7
I118: Retour d'information sur état pompe hydraulique | R118: Num02 | V118: 0 | W118: 16 | X118: INumNetwork.02 | AA118: A | AB118: =AB96+2 -> 1110 | AC118: .0 | AD118: Int (16) | AG118: 1 Byte | AK118: 2ème Word
V119: 1 | W119: 17 | AA119: A | AB119: =AB96+2 -> 1110 | AC119: .1
I120: Valeurs: | J120: 1 | K120: Stop pompe | V120: 2 | W120: 18 | AA120: A | AB120: =AB96+2 -> 1110 | AC120: .2
J121: 2 | K121: Marche pompe | V121: 3 | W121: 19 | AA121: A | AB121: =AB96+2 -> 1110 | AC121: .3
J122: 3 | K122: Défaut pompe | V122: 4 | W122: 20 | AA122: A | AB122: =AB96+2 -> 1110 | AC122: .4 | AF122: [AB | AG122: =AB118 -> 1110 | AH122: ]
J123: 4 | K123: Défaut température huile | V123: 5 | W123: 21 | AA123: A | AB123: =AB96+2 -> 1110 | AC123: .5
J124: 5 | K124: Défaut niveau huile | V124: 6 | W124: 22 | AA124: A | AB124: =AB96+2 -> 1110 | AC124: .6
J125: 6 | K125: Défaut capteur proximité | V125: 7 | W125: 23 | AA125: A | AB125: =AB96+2 -> 1110 | AC125: .7
J126: 7 | K126: Défaut PLC | AJ126: [AW | AK126: =AB118 -> 1110 | AL126: ]
V127: 0 | W127: 24 | AA127: A | AB127: =AB96+3 -> 1111 | AC127: .0 | AG127: 1 Byte
V128: 1 | W128: 25 | AA128: A | AB128: =AB96+3 -> 1111 | AC128: .1
V129: 2 | W129: 26 | AA129: A | AB129: =AB96+3 -> 1111 | AC129: .2
V130: 3 | W130: 27 | AA130: A | AB130: =AB96+3 -> 1111 | AC130: .3
V131: 4 | W131: 28 | AA131: A | AB131: =AB96+3 -> 1111 | AC131: .4 | AF131: [AB | AG131: =AB127 -> 1111 | AH131: ]
...

Sheet Logical Input.PLC->Transceiver
A1: Project : | B1: Tests_Jay_Nemo_MOKA
A2: Customer : | B2: T.EN
A4: Document nr : | B4: /
A7: iDialog software | Y7: STEP7 Siemens software
B8: backup filename: | D8: FPI199FU_ProfibusDP(WHC_V2) | Z8: project name: | AC8: FMC_REMAN_V5_3_JAY
B10: Programmation | Z10: Programmation
D11: Mapping | AC11: Hardware
Y97: Sortie PLC configurée ds HW | AC97: ='HW config'!L18 -> 1100
R99: Radio action | V99: bit | W99: SIEMENS CONDUCTIX | X99: N° | Y99: PLC description | AC99: Input number | AE99: Type
R100: free | V100: 0 | W100: 8 | X100: 0 | Y100: IBoolNetwork.9 | AB100: A | AC100: =AC97 -> 1100 | AD100: .0 | AE100: Boolean | AH100: 1 Byte | AL100: 1er Word | AO100: M1154.0
R101: free | V101: 1 | W101: 9 | X101: 1 | Y101: IBoolNetwork.10 | AB101: A | AC101: =AC97 -> 1100 | AD101: .1 | AE101: Boolean | AO101: M1154.1
R102: free | V102: 2 | W102: 10 | X102: 2 | Y102: IBoolNetwork.11 | AB102: A | AC102: =AC97 -> 1100 | AD102: .2 | AE102: Boolean | AO102: M1154.2
R103: free | V103: 3 | W103: 11 | X103: 3 | Y103: IBoolNetwork.12 | AB103: A | AC103: =AC97 -> 1100 | AD103: .3 | AE103: Boolean | AO103: M1154.3
R104: free | V104: 4 | W104: 12 | X104: 4 | Y104: IBoolNetwork.13 | AB104: A | AC104: =AC97 -> 1100 | AD104: .4 | AE104: Boolean | AG104: [AB | AH104: =AC100 -> 1100 | AI104: ] | AO104: M1154.4
R105: free | V105: 5 | W105: 13 | X105: 5 | Y105: IBoolNetwork.14 | AB105: A | AC105: =AC97 -> 1100 | AD105: .5 | AE105: Boolean | AO105: M1154.5
R106: free | V106: 6 | W106: 14 | X106: 6 | Y106: IBoolNetwork.15 | AB106: A | AC106: =AC97 -> 1100 | AD106: .6 | AE106: Boolean | AO106: M1154.6
R107: free | V107: 7 | W107: 15 | X107: 7 | Y107: IBoolNetwork.16 | AB107: A | AC107: =AC97 -> 1100 | AD107: .7 | AE107: Boolean | AO107: M1154.7
AK108: [AW | AL108: =AC97 -> 1100 | AM108: ]
R109: Pop-Up Alarm 01 : STOP PUMP | V109: 0 | W109: 0 | X109: 8 | Y109: IBoolNetwork.1 | AB109: A | AC109: =AC97+1 -> 1101 | AD109: .0 | AE109: Boolean | AH109: 1 Byte | AO109: M1155.0
R110: Pop-Up Alarm 02 : START PUMP | V110: 1 | W110: 1 | X110: 9 | Y110: IBoolNetwork.2 | AB110: A | AC110: =AC97+1 -> 1101 | AD110: .1 | AE110: Boolean | AO110: M1155.1
R111: Pop-Up Alarm 03 : PUMP FAULT | V111: 2 | W111: 2 | X111: 10 | Y111: IBoolNetwork.3 | AB111: A | AC111: =AC97+1 -> 1101 | AD111: .2 | AE111: Boolean | AO111: M1155.2
R112: Pop-Up Alarm 04 : OIL TEMP. FAULT | V112: 3 | W112: 3 | X112: 11 | Y112: IBoolNetwork.4 | AB112: A | AC112: =AC97+1 -> 1101 | AD112: .3 | AE112: Boolean | AO112: M1155.3
R113: Pop-Up Alarm 04 : OIL LEVEL FAULT | V113: 4 | W113: 4 | X113: 12 | Y113: IBoolNetwork.5 | AB113: A | AC113: =AC97+1 -> 1101 | AD113: .4 | AE113: Boolean | AG113: [AB | AH113: =AC109 -> 1101 | AI113: ] | AO113: M1155.4
R114: Pop-Up Alarm 05 : PROX. SWITCH FAULT | V114: 5 | W114: 5 | X114: 13 | Y114: IBoolNetwork.6 | AB114: A | AC114: =AC97+1 -> 1101 | AD114: .5 | AE114: Boolean | AO114: M1155.5
R115: Pop-Up Alarm 06 : PLC FAULT | V115: 6 | W115: 6 | X115: 14 | Y115: IBoolNetwork.7 | AB115: A | AC115: =AC97+1 -> 1101 | AD115: .6 | AE115: Boolean | AO115: M1155.6
R116: free | V116: 7 | W116: 7 | X116: 15 | Y116: IBoolNetwork.8 | AB116: A | AC116: =AC97+1 -> 1101 | AD116: .7 | AE116: Boolean | AO116: M1155.7
R119: free | V119: 0 | W119: 24 | X119: 16 | Y119: IBoolNetwork.24 | AB119: A | AC119: =AC97+2 -> 1102 | AD119: .0 | AE119: Boolean | AH119: 1 Byte | AL119: 2ème Word
R120: free | V120: 1 | W120: 25 | X120: 17 | Y120: IBoolNetwork.25 | AB120: A | AC120: =AC97+2 -> 1102 | AD120: .1 | AE120: Boolean
R121: free | V121: 2 | W121: 26 | X121: 18 | Y121: IBoolNetwork.26 | AB121: A | AC121: =AC97+2 -> 1102 | AD121: .2 | AE121: Boolean
R122: free | V122: 3 | W122: 27 | X122: 19 | Y122: IBoolNetwork.27 | AB122: A | AC122: =AC97+2 -> 1102 | AD122: .3 | AE122: Boolean
R123: free | V123: 4 | W123: 28 | X123: 20 | Y123: IBoolNetwork.28 | AB123: A | AC123: =AC97+2 -> 1102 | AD123: .4 | AE123: Boolean | AG123: [AB | AH123: =AC119 -> 1102 | AI123: ]
R124: free | V124: 5 | W124: 29 | X124: 21 | Y124: IBoolNetwork.29 | AB124: A | AC124: =AC97+2 -> 1102 | AD124: .5 | AE124: Boolean
R125: free | V125: 6 | W125: 30 | X125: 22 | Y125: IBoolNetwork.30 | AB125: A | AC125: =AC97+2 -> 1102 | AD125: .6 | AE125: Boolean
R126: free | V126: 7 | W126: 31 | X126: 23 | Y126: IBoolNetwork.31 | AB126: A | AC126: =AC97+2 -> 1102 | AD126: .7 | AE126: Boolean
AK127: [AW | AL127: =AC119 -> 1102 | AM127: ]
R128: free | V128: 0 | W128: 16 | X128: 24 | Y128: IBoolNetwork.16 | AB128: A | AC128: =AC97+3 -> 1103 | AD128: .0 | AE128: Boolean | AH128: 1 Byte
R129: free | V129: 1 | W129: 17 | X129: 25 | Y129: IBoolNetwork.17 | AB129: A | AC129: =AC97+3 -> 1103 | AD129: .1 | AE129: Boolean
R130: free | V130: 2 | W130: 18 | X130: 26 | Y130: IBoolNetwork.18 | AB130: A | AC130: =AC97+3 -> 1103 | AD130: .2 | AE130: Boolean
R131: free | V131: 3 | W131: 19 | X131: 27 | Y131: IBoolNetwork.19 | AB131: A | AC131: =AC97+3 -> 1103 | AD131: .3 | AE131: Boolean
R132: free | V132: 4 | W132: 20 | X132: 28 | Y132: IBoolNetwork.20 | AB132: A | AC132: =AC97+3 -> 1103 | AD132: .4 | AE132: Boolean | AG132: [AB | AH132: =AC128 -> 1103 | AI132: ]
...

Sheet WHC
A1: Project : | B1: Tests_Jay_Nemo_MOKA
A2: Customer : | B2: T.EN
A4: Document nr : | B4: /
A7: iDialog software | Y7: STEP7 Siemens software
B8: backup filename: | D8: FPI199FU_ProfibusDP(WHC_V2) | Z8: project name: | AC8: FMC_REMAN_V5_0_JAY
B10: Programmation | Z10: Programmation
D11: Mapping | AC11: Hardware
Y106: Sortie PLC configurée ds HW | AC106: ='HW config'!L20 -> 1140
R108: Radio action | V108: bit | W108: SIEMENS CONDUCTIX | X108: N° | Y108: PLC description | AC108: Input number | AE108: Type
R109: free | V109: 0 | W109: 8 | X109: 0 | Y109: IWHC.8 | AB109: A | AC109: =AC106 -> 1140 | AD109: .0 | AE109: Boolean | AH109: 1 Byte | AL109: 1er Word
R110: free | V110: 1 | W110: 9 | X110: 1 | Y110: IWHC.9 | AB110: A | AC110: =AC106 -> 1140 | AD110: .1 | AE110: Boolean
R111: free | V111: 2 | W111: 10 | X111: 2 | Y111: IWHC.10 | AB111: A | AC111: =AC106 -> 1140 | AD111: .2 | AE111: Boolean
R112: free | V112: 3 | W112: 11 | X112: 3 | Y112: IWHC.11 | AB112: A | AC112: =AC106 -> 1140 | AD112: .3 | AE112: Boolean | AS112: b31 | AT112: b30 | AU112: b29 | AV112: b28 | AX112: b27 | AY112: b26 | AZ112: b25 | BA112: b24 | BC112: b23 | BD112: b22 | BE112: b21 | BF112: b20 | BH112: b19 | BI112: b18 | BJ112: b17 | BK112: b16 | BM112: b15 | BN112: b14 | BO112: b13 | BP112: b12 | BR112: b11 | BS112: b10 | BT112: b9 | BU112: b8 | BW112: b7 | BX112: b6 | BY112: b5 | BZ112: b4 | CB112: b3 | CC112: b2 | CD112: b1 | CE112: b0
R113: NOT USED | V113: 4 | W113: 12 | X113: 4 | Y113: IWHC.12 | AB113: A | AC113: =AC106 -> 1140 | AD113: .4 | AE113: Boolean | AG113: [AB | AH113: =AC109 -> 1140 | AI113: ] | AS113: 0 | AT113: 0 | AU113: 0 | AV113: 0 | AX113: 0 | AY113: 0 | AZ113: 0 | BA113: 0 | BC113: 0 | BD113: 0 | BE113: 0 | BF113: 1 | BH113: 0 | BI113: 0 | BJ113: 0 | BK113: 1 | BM113: 0 | BN113: 0 | BO113: 0 | BP113: 0 | BR113: 0 | BS113: 0 | BT113: 0 | BU113: 0 | BW113: 0 | BX113: 1 | BY113: 0 | BZ113: 0 | CB113: 0 | CC113: 0 | CD113: 0 | CE113: 1
R114: NOT USED | V114: 5 | W114: 13 | X114: 5 | Y114: IWHC.13 | AB114: A | AC114: =AC106 -> 1140 | AD114: .5 | AE114: Boolean
R115: NOT USED | V115: 6 | W115: 14 | X115: 6 | Y115: IWHC.14 | AB115: A | AC115: =AC106 -> 1140 | AD115: .6 | AE115: Boolean | AS115: 0 | AX115: 0 | BC115: 1 | BH115: 1 | BM115: 0 | BR115: 0 | BW115: 4 | CB115: 1
R116: NOT USED | V116: 7 | W116: 15 | X116: 7 | Y116: IWHC.15 | AB116: A | AC116: =AC106 -> 1140 | AD116: .7 | AE116: Boolean
AK117: [AW | AL117: =AC106 -> 1140 | AM117: ]
R118: free | V118: 0 | W118: 0 | X118: 8 | Y118: IWHC.0 | AB118: A | AC118: =AC106+1 -> 1141 | AD118: .0 | AE118: Boolean | AH118: 1 Byte
R119: free | V119: 1 | W119: 1 | X119: 9 | Y119: IWHC.1 | AB119: A | AC119: =AC106+1 -> 1141 | AD119: .1 | AE119: Boolean
R120: free | V120: 2 | W120: 2 | X120: 10 | Y120: IWHC.2 | AB120: A | AC120: =AC106+1 -> 1141 | AD120: .2 | AE120: Boolean | AZ120: AW | BA120: =AC106 -> 1140 | BT120: AW | BU120: =AC128 -> 1142
R121: free | V121: 3 | W121: 3 | X121: 11 | Y121: IWHC.3 | AB121: A | AC121: =AC106+1 -> 1141 | AD121: .3 | AE121: Boolean
R122: free | V122: 4 | W122: 4 | X122: 12 | Y122: IWHC.4 | AB122: A | AC122: =AC106+1 -> 1141 | AD122: .4 | AE122: Boolean | AG122: [AB | AH122: =AC118 -> 1141 | AI122: ]
R123: free | V123: 5 | W123: 5 | X123: 13 | Y123: IWHC.5 | AB123: A | AC123: =AC106+1 -> 1141 | AD123: .5 | AE123: Boolean
R124: free | V124: 6 | W124: 6 | X124: 14 | Y124: IWHC.6 | AB124: A | AC124: =AC106+1 -> 1141 | AD124: .6 | AE124: Boolean
R125: free | V125: 7 | W125: 7 | X125: 15 | Y125: IWHC.7 | AB125: A | AC125: =AC106+1 -> 1141 | AD125: .7 | AE125: Boolean
R128: NOT USED | V128: 0 | W128: 24 | X128: 16 | Y128: IWHC.24 | AB128: A | AC128: =AC106+2 -> 1142 | AD128: .0 | AE128: Boolean | AH128: 1 Byte | AL128: 2ème Word
R129: NOT USED | V129: 1 | W129: 25 | X129: 17 | Y129: IWHC.25 | AB129: E | AC129: =AC106+2 -> 1142 | AD129: .1 | AE129: Boolean
R130: NOT USED | V130: 2 | W130: 26 | X130: 18 | Y130: IWHC.26 | AB130: E | AC130: =AC106+2 -> 1142 | AD130: .2 | AE130: Boolean
R131: NOT USED | V131: 3 | W131: 27 | X131: 19 | Y131: IWHC.27 | AB131: E | AC131: =AC106+2 -> 1142 | AD131: .3 | AE131: Boolean
R132: NOT USED | V132: 4 | W132: 28 | X132: 20 | Y132: IWHC.28 | AB132: E | AC132: =AC106+2 -> 1142 | AD132: .4 | AE132: Boolean | AG132: [AB | AH132: =AC128 -> 1142 | AI132: ]
R133: NOT USED | V133: 5 | W133: 29 | X133: 21 | Y133: IWHC.29 | AB133: E | AC133: =AC106+2 -> 1142 | AD133: .5 | AE133: Boolean
R134: NOT USED | V134: 6 | W134: 30 | X134: 22 | Y134: IWHC.30 | AB134: E | AC134: =AC106+2 -> 1142 | AD134: .6 | AE134: Boolean
R135: NOT USED | V135: 7 | W135: 31 | X135: 23 | Y135: IWHC.31 | AB135: E | AC135: =AC106+2 -> 1142 | AD135: .7 | AE135: Boolean
AK136: [AW | AL136: =AC128 -> 1142 | AM136: ]
R137: free | V137: 0 | W137: 16 | X137: 24 | Y137: IWHC.16 | AB137: A | AC137: =AC106+3 -> 1143 | AD137: .0 | AE137: Boolean | AH137: 1 Byte
R138: free | V138: 1 | W138: 17 | X138: 25 | Y138: IWHC.17 | AB138: A | AC138: =AC106+3 -> 1143 | AD138: .1 | AE138: Boolean
R139: free | V139: 2 | W139: 18 | X139: 26 | Y139: IWHC.18 | AB139: A | AC139: =AC106+3 -> 1143 | AD139: .2 | AE139: Boolean
R140: free | V140: 3 | W140: 19 | X140: 27 | Y140: IWHC.19 | AB140: A | AC140: =AC106+3 -> 1143 | AD140: .3 | AE140: Boolean
R141: free | V141: 4 | W141: 20 | X141: 28 | Y141: IWHC.20 | AB141: A | AC141: =AC106+3 -> 1143 | AD141: .4 | AE141: Boolean | AG141: [AB | AH141: =AC137 -> 1143 | AI141: ]
...

Sheet WHC à programmer
A1: Project : | B1: Tests_Jay_Nemo_MOKA
A2: Customer : | B2: T.EN
A4: Document nr : | B4: /
A7: Adressages pour chaque image WHC à programmer dans le PLC:
G9: Ce que nous voulons obtenir sur notre écran radio:
D34: appel de l'image B1 en: | G34: $11 | AM34: appel de l'image B6 en: | AS34: $1B
D38: appel de l'image B2 en: | G38: $31 | AM38: appel de l'image B7 en: | AS38: $3B
D42: appel de l'image B3 en: | G42: $51 | AM42: appel de l'image B8 en: | AS42: $5B
D47: appel de l'image B4 en: | G47: $71 | AM47: appel de l'image B9 en: | AS47: $7B
D51: appel de l'image B5 en: | G51: $91 | AM51: appel de l'image B10 en: | AS51: $9B
G65: rappel:
H77: 2^3 | I77: 2^2 | J77: 2^1 | K77: 2^0 | M77: 2^3 | N77: 2^2 | O77: 2^1 | P77: 2^0 | R77: 2^3 | S77: 2^2 | T77: 2^1 | U77: 2^0 | W77: 2^3 | X77: 2^2 | Y77: 2^1 | Z77: 2^0 | AB77: 2^3 | AC77: 2^2 | AD77: 2^1 | AE77: 2^0 | AG77: 2^3 | AH77: 2^2 | AI77: 2^1 | AJ77: 2^0 | AL77: 2^3 | AM77: 2^2 | AN77: 2^1 | AO77: 2^0 | AQ77: 2^3 | AR77: 2^2 | AS77: 2^1 | AT77: 2^0
H78: 8 | I78: 4 | J78: 2 | K78: 1 | M78: 8 | N78: 4 | O78: 2 | P78: 1 | R78: 8 | S78: 4 | T78: 2 | U78: 1 | W78: 8 | X78: 4 | Y78: 2 | Z78: 1 | AB78: 8 | AC78: 4 | AD78: 2 | AE78: 1 | AG78: 8 | AH78: 4 | AI78: 2 | AJ78: 1 | AL78: 8 | AM78: 4 | AN78: 2 | AO78: 1 | AQ78: 8 | AR78: 4 | AS78: 2 | AT78: 1
H79: b31 | I79: b30 | J79: b29 | K79: b28 | M79: b27 | N79: b26 | O79: b25 | P79: b24 | R79: b23 | S79: b22 | T79: b21 | U79: b20 | W79: b19 | X79: b18 | Y79: b17 | Z79: b16 | AB79: b15 | AC79: b14 | AD79: b13 | AE79: b12 | AG79: b11 | AH79: b10 | AI79: b9 | AJ79: b8 | AL79: b7 | AM79: b6 | AN79: b5 | AO79: b4 | AQ79: b3 | AR79: b2 | AS79: b1 | AT79: b0
H80: 0 | I80: 0 | J80: 0 | K80: 0 | M80: 0 | N80: 0 | O80: 0 | P80: 0 | R80: ? | S80: ? | T80: ? | U80: ? | W80: ? | X80: ? | Y80: ? | Z80: ? | AB80: 0 | AC80: 0 | AD80: 0 | AE80: 0 | AG80: 0 | AH80: 0 | AI80: 0 | AJ80: 1 | AL80: ? | AM80: ? | AN80: ? | AO80: ? | AQ80: ? | AR80: ? | AS80: ? | AT80: ?
H84: Adresse [$0000]pour afficher l'image [B1] en [$11]: | BE84: Lignes de code dans programme PLC: | CN84: Affichage sur l'écran de la radio JAY type MOKA:
H86: 2^3 | I86: 2^2 | J86: 2^1 | K86: 2^0 | M86: 2^3 | N86: 2^2 | O86: 2^1 | P86: 2^0 | R86: 2^3 | S86: 2^2 | T86: 2^1 | U86: 2^0 | W86: 2^3 | X86: 2^2 | Y86: 2^1 | Z86: 2^0 | AB86: 2^3 | AC86: 2^2 | AD86: 2^1 | AE86: 2^0 | AG86: 2^3 | AH86: 2^2 | AI86: 2^1 | AJ86: 2^0 | AL86: 2^3 | AM86: 2^2 | AN86: 2^1 | AO86: 2^0 | AQ86: 2^3 | AR86: 2^2 | AS86: 2^1 | AT86: 2^0
H87: 8 | I87: 4 | J87: 2 | K87: 1 | M87: 8 | N87: 4 | O87: 2 | P87: 1 | R87: 8 | S87: 4 | T87: 2 | U87: 1 | W87: 8 | X87: 4 | Y87: 2 | Z87: 1 | AB87: 8 | AC87: 4 | AD87: 2 | AE87: 1 | AG87: 8 | AH87: 4 | AI87: 2 | AJ87: 1 | AL87: 8 | AM87: 4 | AN87: 2 | AO87: 1 | AQ87: 8 | AR87: 4 | AS87: 2 | AT87: 1
H88: b31 | I88: b30 | J88: b29 | K88: b28 | M88: b27 | N88: b26 | O88: b25 | P88: b24 | R88: b23 | S88: b22 | T88: b21 | U88: b20 | W88: b19 | X88: b18 | Y88: b17 | Z88: b16 | AB88: b15 | AC88: b14 | AD88: b13 | AE88: b12 | AG88: b11 | AH88: b10 | AI88: b9 | AJ88: b8 | AL88: b7 | AM88: b6 | AN88: b5 | AO88: b4 | AQ88: b3 | AR88: b2 | AS88: b1 | AT88: b0
H89: 0 | I89: 0 | J89: 0 | K89: 0 | M89: 0 | N89: 0 | O89: 0 | P89: 0 | R89: 0 | S89: 0 | T89: 0 | U89: 1 | W89: 0 | X89: 0 | Y89: 0 | Z89: 1 | AB89: 0 | AC89: 0 | AD89: 0 | AE89: 0 | AG89: 0 | AH89: 0 | AI89: 0 | AJ89: 1 | AL89: 0 | AM89: 0 | AN89: 0 | AO89: 0 | AQ89: 0 | AR89: 0 | AS89: 0 | AT89: 0
H91: 0 | M91: 0 | R91: 1 | W91: 1 | AB91: 0 | AG91: 1 | AL91: 0 | AQ91: 0
O96: AW | P96: =WHC!AC106 -> 1140 | AI96: AW | AJ96: =WHC!AC128 -> 1142
BE106: Lignes de code dans programme PLC:
H125: Adresse [$0002]pour afficher l'image [B1] en [$11]: | BE125: Lignes de code dans programme PLC: | CN125: Affichage sur l'écran de la radio JAY type MOKA:
H127: 2^3 | I127: 2^2 | J127: 2^1 | K127: 2^0 | M127: 2^3 | N127: 2^2 | O127: 2^1 | P127: 2^0 | R127: 2^3 | S127: 2^2 | T127: 2^1 | U127: 2^0 | W127: 2^3 | X127: 2^2 | Y127: 2^1 | Z127: 2^0 | AB127: 2^3 | AC127: 2^2 | AD127: 2^1 | AE127: 2^0 | AG127: 2^3 | AH127: 2^2 | AI127: 2^1 | AJ127: 2^0 | AL127: 2^3 | AM127: 2^2 | AN127: 2^1 | AO127: 2^0 | AQ127: 2^3 | AR127: 2^2 | AS127: 2^1 | AT127: 2^0
H128: 8 | I128: 4 | J128: 2 | K128: 1 | M128: 8 | N128: 4 | O128: 2 | P128: 1 | R128: 8 | S128: 4 | T128: 2 | U128: 1 | W128: 8 | X128: 4 | Y128: 2 | Z128: 1 | AB128: 8 | AC128: 4 | AD128: 2 | AE128: 1 | AG128: 8 | AH128: 4 | AI128: 2 | AJ128: 1 | AL128: 8 | AM128: 4 | AN128: 2 | AO128: 1 | AQ128: 8 | AR128: 4 | AS128: 2 | AT128: 1
H129: b31 | I129: b30 | J129: b29 | K129: b28 | M129: b27 | N129: b26 | O129: b25 | P129: b24 | R129: b23 | S129: b22 | T129: b21 | U129: b20 | W129: b19 | X129: b18 | Y129: b17 | Z129: b16 | AB129: b15 | AC129: b14 | AD129: b13 | AE129: b12 | AG129: b11 | AH129: b10 | AI129: b9 | AJ129: b8 | AL129: b7 | AM129: b6 | AN129: b5 | AO129: b4 | AQ129: b3 | AR129: b2 | AS129: b1 | AT129: b0
H130: 0 | I130: 0 | J130: 0 | K130: 0 | M130: 0 | N130: 0 | O130: 0 | P130: 0 | R130: 0 | S130: 0 | T130: 0 | U130: 1 | W130: 0 | X130: 0 | Y130: 0 | Z130: 1 | AB130: 0 | AC130: 0 | AD130: 0 | AE130: 0 | AG130: 0 | AH130: 0 | AI130: 0 | AJ130: 1 | AL130: 0 | AM130: 0 | AN130: 0 | AO130: 0 | AQ130: 0 | AR130: 0 | AS130: 1 | AT130: 0
H132: 0 | M132: 0 | R132: 1 | W132: 1 | AB132: 0 | AG132: 1 | AL132: 0 | AQ132: 2
CF134: A METTRE A JOUR / IMAGE
O137: AW | P137: =WHC!AC106 -> 1140 | AI137: AW | AJ137: =WHC!AC128 -> 1142
H154: Adresse [$0001]pour afficher l'image [B1] en [$11]: | BE154: Lignes de code dans programme PLC:
CN155: Affichage sur l'écran de la radio JAY type MOKA:
H156: 2^3 | I156: 2^2 | J156: 2^1 | K156: 2^0 | M156: 2^3 | N156: 2^2 | O156: 2^1 | P156: 2^0 | R156: 2^3 | S156: 2^2 | T156: 2^1 | U156: 2^0 | W156: 2^3 | X156: 2^2 | Y156: 2^1 | Z156: 2^0 | AB156: 2^3 | AC156: 2^2 | AD156: 2^1 | AE156: 2^0 | AG156: 2^3 | AH156: 2^2 | AI156: 2^1 | AJ156: 2^0 | AL156: 2^3 | AM156: 2^2 | AN156: 2^1 | AO156: 2^0 | AQ156: 2^3 | AR156: 2^2 | AS156: 2^1 | AT156: 2^0
H157: 8 | I157: 4 | J157: 2 | K157: 1 | M157: 8 | N157: 4 | O157: 2 | P157: 1 | R157: 8 | S157: 4 | T157: 2 | U157: 1 | W157: 8 | X157: 4 | Y157: 2 | Z157: 1 | AB157: 8 | AC157: 4 | AD157: 2 | AE157: 1 | AG157: 8 | AH157: 4 | AI157: 2 | AJ157: 1 | AL157: 8 | AM157: 4 | AN157: 2 | AO157: 1 | AQ157: 8 | AR157: 4 | AS157: 2 | AT157: 1
H158: b31 | I158: b30 | J158: b29 | K158: b28 | M158: b27 | N158: b26 | O158: b25 | P158: b24 | R158: b23 | S158: b22 | T158: b21 | U158: b20 | W158: b19 | X158: b18 | Y158: b17 | Z158: b16 | AB158: b15 | AC158: b14 | AD158: b13 | AE158: b12 | AG158: b11 | AH158: b10 | AI158: b9 | AJ158: b8 | AL158: b7 | AM158: b6 | AN158: b5 | AO158: b4 | AQ158: b3 | AR158: b2 | AS158: b1 | AT158: b0
H159: 0 | I159: 0 | J159: 0 | K159: 0 | M159: 0 | N159: 0 | O159: 0 | P159: 0 | R159: 0 | S159: 0 | T159: 0 | U159: 1 | W159: 0 | X159: 0 | Y159: 0 | Z159: 1 | AB159: 0 | AC159: 0 | AD159: 0 | AE159: 0 | AG159: 0 | AH159: 0 | AI159: 0 | AJ159: 1 | AL159: 0 | AM159: 0 | AN159: 0 | AO159: 0 | AQ159: 0 | AR159: 0 | AS159: 0 | AT159: 1
H161: 0 | M161: 0 | R161: 1 | W161: 1 | AB161: 0 | AG161: 1 | AL161: 0 | AQ161: 1
CF164: A METTRE A JOUR / IMAGE
O166: AW | P166: =WHC!AC106 -> 1140 | AI166: AW | AJ166: =WHC!AC128 -> 1142
